<?xml version="1.0" ?>
<sdf version="1.8">
  <model name="tutorial_diff_bot" canonical_link="base_link">
    <pose>0 0 0 0 0 0</pose>

    <link name="base_link">
      <pose>0 0 0.4 0 0 0</pose>
      <inertial>
        <mass>1.14395</mass>
        <inertia>
          <ixx>0.095329</ixx>
          <ixy>0</ixy>
          <ixz>0</ixz>
          <iyy>0.381317</iyy>
          <iyz>0</iyz>
          <izz>0.476646</izz>
        </inertia>
      </inertial>

      <visual name="visual">
        <geometry>
          <box>
            <size>2.0 1.0 0.5</size>
          </box>
        </geometry>
        <material>
          <ambient>0.0 0.0 1.0 1</ambient>
          <diffuse>0.0 0.0 1.0 1</diffuse>
          <specular>0.0 0.0 1.0 1</specular>
        </material>
      </visual>

      <collision name="collision">
        <geometry>
          <box>
            <size>2.0 1.0 0.5</size>
          </box>
        </geometry>
      </collision>

      <!-- LIDAR MUST BE INSIDE A LINK -->

      <sensor name="gpu_lidar" type="gpu_lidar">
	      <pose relative_to="laser_frame">0 0 0 0 0 0</pose>
	      <always_on>true</always_on>
	      <visualize>true</visualize>
	      <update_rate>10</update_rate>
	      <topic>/scan</topic>
	      <gz_frame_id>laser_frame</gz_frame_id>
	      <lidar>
		      <scan>
			      <horizontal>
				      <samples>720</samples>
				      <resolution>1</resolution>
				      <min_angle>-3.14159</min_angle>
				      <max_angle>3.14159</max_angle>
			      </horizontal>
		      </scan>
		      <range>
			      <min>0.10</min>
			      <max>30.0</max>
			      <resolution>0.01</resolution>
		      </range>
	      </lidar>
      </sensor>

    </link>

    <frame name="laser_frame" attached_to="base_link">
	    <pose>0 0 0.35 0 0 0</pose>
    </frame>

    <link name="left_wheel">
      <pose relative_to="base_link">-0.5 0.6 0 -1.5707 0 0</pose>
      <inertial>
        <mass>1</mass>
        <inertia>
          <ixx>0.043333</ixx>
          <ixy>0</ixy>
          <ixz>0</ixz>
          <iyy>0.043333</iyy>
          <iyz>0</iyz>
          <izz>0.08</izz>
        </inertia>
      </inertial>
      <visual name="visual">
        <geometry>
          <cylinder>
            <radius>0.4</radius>
            <length>0.2</length>
          </cylinder>
        </geometry>
        <material>
          <ambient>1.0 0.0 0.0 1</ambient>
          <diffuse>1.0 0.0 0.0 1</diffuse>
          <specular>1.0 0.0 0.0 1</specular>
        </material>
      </visual>
      <collision name="collision">
        <geometry>
          <cylinder>
            <radius>0.4</radius>
            <length>0.2</length>
          </cylinder>
        </geometry>
        <surface>
          <friction>
            <ode>
              <mu>5.0</mu>
              <mu2>5.0</mu2>
            </ode>
          </friction>
        </surface>
      </collision>
    </link>

    <link name="right_wheel">
      <pose relative_to="base_link">-0.5 -0.6 0 -1.5707 0 0</pose>
      <inertial>
        <mass>1</mass>
        <inertia>
          <ixx>0.043333</ixx>
          <ixy>0</ixy>
          <ixz>0</ixz>
          <iyy>0.043333</iyy>
          <iyz>0</iyz>
          <izz>0.08</izz>
        </inertia>
      </inertial>
      <visual name="visual">
        <geometry>
          <cylinder>
            <radius>0.4</radius>
            <length>0.2</length>
          </cylinder>
        </geometry>
        <material>
          <ambient>1.0 0.0 0.0 1</ambient>
          <diffuse>1.0 0.0 0.0 1</diffuse>
          <specular>1.0 0.0 0.0 1</specular>
        </material>
      </visual>
      <collision name="collision">
        <geometry>
          <cylinder>
            <radius>0.4</radius>
            <length>0.2</length>
          </cylinder>
        </geometry>
        <surface>
          <friction>
            <ode>
              <mu>5.0</mu>
              <mu2>5.0</mu2>
            </ode>
          </friction>
        </surface>
      </collision>
    </link>

    <frame name="caster_frame" attached_to="base_link">
      <pose>0.8 0 -0.2 0 0 0</pose>
    </frame>

    <link name="caster">
      <pose relative_to="caster_frame"/>
      <inertial>
        <mass>1</mass>
        <inertia>
          <ixx>0.016</ixx>
          <ixy>0</ixy>
          <ixz>0</ixz>
          <iyy>0.016</iyy>
          <iyz>0</iyz>
          <izz>0.016</izz>
        </inertia>
      </inertial>
      <visual name="visual">
        <geometry>
          <sphere>
            <radius>0.2</radius>
          </sphere>
        </geometry>
        <material>
          <ambient>0.0 1 0.0 1</ambient>
          <diffuse>0.0 1 0.0 1</diffuse>
          <specular>0.0 1 0.0 1</specular>
        </material>
      </visual>
      <collision name="collision">
        <geometry>
          <sphere>
            <radius>0.2</radius>
          </sphere>
        </geometry>
      </collision>
    </link>

    <joint name="left_wheel_joint" type="revolute">
      <parent>base_link</parent>
      <child>left_wheel</child>
      <axis>
        <xyz expressed_in="__model__">0 1 0</xyz>
        <limit>
          <lower>-1.79769e+308</lower>
          <upper>1.79769e+308</upper>
        </limit>
      </axis>
    </joint>

    <joint name="right_wheel_joint" type="revolute">
      <parent>base_link</parent>
      <child>right_wheel</child>
      <axis>
        <xyz expressed_in="__model__">0 1 0</xyz>
        <limit>
          <lower>-1.79769e+308</lower>
          <upper>1.79769e+308</upper>
        </limit>
      </axis>
    </joint>

    <joint name="caster_wheel" type="ball">
      <parent>base_link</parent>
      <child>caster</child>
    </joint>

    <plugin
	    filename="gz-sim-diff-drive-system"
	    name="gz::sim::systems::DiffDrive">
    <left_joint>left_wheel_joint</left_joint>
    <right_joint>right_wheel_joint</right_joint>
    <wheel_separation>1.2</wheel_separation>
    <wheel_radius>0.4</wheel_radius>
    <odom_publish_frequency>30</odom_publish_frequency>
    <topic>/cmd_vel</topic>
    <odom_topic>/odom</odom_topic>
    <tf_topic>/tf</tf_topic>
    <frame_id>odom</frame_id>
    <child_frame_id>base_link</child_frame_id>
</plugin>

  </model>
</sdf>
